<?xml version="1.0" encoding="utf-8"?>
<!-- This URDF was automatically created by SolidWorks to URDF Exporter! Originally created by Stephen Brawner (brawner@gmail.com) 
     Commit Version: 1.6.0-4-g7f85cfe  Build Version: 1.6.7995.38578
     For more information, please see http://wiki.ros.org/sw_urdf_exporter -->
<robot
  name="threefingerv8">
  <link
    name="base_link">
    <inertial>
      <origin
        xyz="-0.000178369551553661 0.00149077290750217 -0.000359711928960869"
        rpy="0 0 0" />
      <mass
        value="0.158098732405424" />
      <inertia
        ixx="0.000153851216242209"
        ixy="-1.14272913956443E-06"
        ixz="1.10735125502593E-08"
        iyy="0.000217118434161234"
        iyz="-1.96328376479071E-06"
        izz="0.000154504336827899" />
    </inertial>
    <visual>
      <origin
        xyz="0 0 0"
        rpy="0 0 0" />
      <geometry>
        <mesh
          filename="package://threefingerv8/meshes/base_link.STL" />
      </geometry>
      <material
        name="">
        <color
          rgba="1 1 1 1" />
      </material>
    </visual>
    <collision>
      <origin
        xyz="0 0 0"
        rpy="0 0 0" />
      <geometry>
        <mesh
          filename="package://threefingerv8/meshes/base_link.STL" />
      </geometry>
    </collision>
  </link>
  <link
    name="move_link">
    <inertial>
      <origin
        xyz="2.12982875964774E-17 0.00680756785766646 -1.40497362985593E-17"
        rpy="0 0 0" />
      <mass
        value="0.0085021271877303" />
      <inertia
        ixx="9.76418874057011E-07"
        ixy="5.21940490933867E-23"
        ixz="2.76643146367182E-21"
        iyy="1.86965817859979E-06"
        iyz="-2.18801958274866E-23"
        izz="9.76418874057014E-07" />
    </inertial>
    <visual>
      <origin
        xyz="0 0 0"
        rpy="0 0 0" />
      <geometry>
        <mesh
          filename="package://threefingerv8/meshes/move_link.STL" />
      </geometry>
      <material
        name="">
        <color
          rgba="1 1 1 1" />
      </material>
    </visual>
    <collision>
      <origin
        xyz="0 0 0"
        rpy="0 0 0" />
      <geometry>
        <mesh
          filename="package://threefingerv8/meshes/move_link.STL" />
      </geometry>
    </collision>
  </link>
  <joint
    name="move_joint"
    type="prismatic">
    <origin
      xyz="0 0 0.024087"
      rpy="1.5708 0 0" />
    <parent
      link="base_link" />
    <child
      link="move_link" />
    <axis
      xyz="0 1 0" />
    <limit
      lower="-0.5"
      upper="0.5"
      effort="5000"
      velocity="2" />
  </joint>
  <link
    name="11_link">
    <inertial>
      <origin
        xyz="-0.00649999999998663 -1.10866177349678E-14 0.015"
        rpy="0 0 0" />
      <mass
        value="0.0023425840131754" />
      <inertia
        ixx="4.99013749037845E-07"
        ixy="0"
        ixz="-4.5306118998929E-24"
        iyy="5.48312815441792E-07"
        iyz="-5.81408815034905E-23"
        izz="7.32310540795453E-08" />
    </inertial>
    <visual>
      <origin
        xyz="0 0 0"
        rpy="0 0 0" />
      <geometry>
        <mesh
          filename="package://threefingerv8/meshes/11_link.STL" />
      </geometry>
      <material
        name="">
        <color
          rgba="1 1 1 1" />
      </material>
    </visual>
    <collision>
      <origin
        xyz="0 0 0"
        rpy="0 0 0" />
      <geometry>
        <mesh
          filename="package://threefingerv8/meshes/11_link.STL" />
      </geometry>
    </collision>
  </link>
  <joint
    name="11_joint"
    type="revolute">
    <origin
      xyz="0.015 0.007 -0.0195"
      rpy="1.5708 -0.43528 -1.5708" />
    <parent
      link="move_link" />
    <child
      link="11_link" />
    <axis
      xyz="0 0 -1" />
    <limit
      lower="-1.57"
      upper="1.57"
      effort="5000"
      velocity="2" />
    <mimic
      joint="move_joint"
      multiplier="1"
      offset="0" />
  </joint>
  <link
    name="12_link">
    <inertial>
      <origin
        xyz="-0.0293208969248082 -0.00876107376234852 0.0190000001135646"
        rpy="0 0 0" />
      <mass
        value="0.0122579255984349" />
      <inertia
        ixx="9.8466089201607E-07"
        ixy="1.31799544484654E-06"
        ixz="-2.57676351638825E-14"
        iyy="7.20160465350243E-06"
        iyz="1.09652705676399E-14"
        izz="7.77283391142853E-06" />
    </inertial>
    <visual>
      <origin
        xyz="0 0 0"
        rpy="0 0 0" />
      <geometry>
        <mesh
          filename="package://threefingerv8/meshes/12_link.STL" />
      </geometry>
      <material
        name="">
        <color
          rgba="1 1 1 1" />
      </material>
    </visual>
    <collision>
      <origin
        xyz="0 0 0"
        rpy="0 0 0" />
      <geometry>
        <mesh
          filename="package://threefingerv8/meshes/12_link.STL" />
      </geometry>
    </collision>
  </link>
  <joint
    name="12_joint"
    type="revolute">
    <origin
      xyz="-0.013 0 -0.004"
      rpy="0 0 0" />
    <parent
      link="11_link" />
    <child
      link="12_link" />
    <axis
      xyz="0 0 -1" />
    <limit
      lower="-1.57"
      upper="1.57"
      effort="5000"
      velocity="2" />
    <mimic
      joint="11_joint"
      multiplier="1"
      offset="0" />
  </joint>
  <link
    name="21_link">
    <inertial>
      <origin
        xyz="0.00649999999998662 -1.10068204550728E-14 -0.019"
        rpy="0 0 0" />
      <mass
        value="0.0023425840131754" />
      <inertia
        ixx="4.99013749037845E-07"
        ixy="-8.60267837055149E-23"
        ixz="-1.05879118406788E-22"
        iyy="5.48312815441792E-07"
        iyz="-6.94831714544543E-23"
        izz="7.32310540795453E-08" />
    </inertial>
    <visual>
      <origin
        xyz="0 0 0"
        rpy="0 0 0" />
      <geometry>
        <mesh
          filename="package://threefingerv8/meshes/21_link.STL" />
      </geometry>
      <material
        name="">
        <color
          rgba="1 1 1 1" />
      </material>
    </visual>
    <collision>
      <origin
        xyz="0 0 0"
        rpy="0 0 0" />
      <geometry>
        <mesh
          filename="package://threefingerv8/meshes/21_link.STL" />
      </geometry>
    </collision>
  </link>
  <joint
    name="21_joint"
    type="revolute">
    <origin
      xyz="-0.0263874953737968 0.00700000000001386 -0.00670448267190406"
      rpy="-2.65931138123083 -0.212425490096555 1.95364858543396" />
    <parent
      link="move_link" />
    <child
      link="21_link" />
    <axis
      xyz="0 0 1" />
    <limit
      lower="-1.57"
      upper="1.57"
      effort="5000"
      velocity="2" />
    <mimic
      joint="move_joint"
      multiplier="1"
      offset="0" />
  </joint>
  <link
    name="22_link">
    <inertial>
      <origin
        xyz="0.0293216343766779 -0.00876108435080183 -0.0190000103494336"
        rpy="0 0 0" />
      <mass
        value="0.0122572499897457" />
      <inertia
        ixx="9.84650226311452E-07"
        ixy="-1.31798330895562E-06"
        ixz="-1.09743409221826E-12"
        iyy="7.20145547037363E-06"
        iyz="3.40750819919882E-13"
        izz="7.77268089083732E-06" />
    </inertial>
    <visual>
      <origin
        xyz="0 0 0"
        rpy="0 0 0" />
      <geometry>
        <mesh
          filename="package://threefingerv8/meshes/22_link.STL" />
      </geometry>
      <material
        name="">
        <color
          rgba="1 1 1 1" />
      </material>
    </visual>
    <collision>
      <origin
        xyz="0 0 0"
        rpy="0 0 0" />
      <geometry>
        <mesh
          filename="package://threefingerv8/meshes/22_link.STL" />
      </geometry>
    </collision>
  </link>
  <joint
    name="22_joint"
    type="revolute">
    <origin
      xyz="0.013 0 0"
      rpy="0 0 0" />
    <parent
      link="21_link" />
    <child
      link="22_link" />
    <axis
      xyz="0 0 1" />
    <limit
      lower="-1.57"
      upper="1.57"
      effort="5000"
      velocity="2" />
    <mimic
      joint="21_joint"
      multiplier="1"
      offset="0" />
  </joint>
  <link
    name="31_link">
    <inertial>
      <origin
        xyz="-0.00649999999998662 -1.10796788410639E-14 0.019"
        rpy="0 0 0" />
      <mass
        value="0.0023425840131754" />
      <inertia
        ixx="4.99013749037844E-07"
        ixy="4.63221143029695E-23"
        ixz="-1.40620704134015E-23"
        iyy="5.48312815441792E-07"
        iyz="1.86942818436984E-22"
        izz="7.32310540795452E-08" />
    </inertial>
    <visual>
      <origin
        xyz="0 0 0"
        rpy="0 0 0" />
      <geometry>
        <mesh
          filename="package://threefingerv8/meshes/31_link.STL" />
      </geometry>
      <material
        name="">
        <color
          rgba="1 1 1 1" />
      </material>
    </visual>
    <collision>
      <origin
        xyz="0 0 0"
        rpy="0 0 0" />
      <geometry>
        <mesh
          filename="package://threefingerv8/meshes/31_link.STL" />
      </geometry>
    </collision>
  </link>
  <joint
    name="31_joint"
    type="revolute">
    <origin
      xyz="0.00738749537379796 0.00700000000001319 0.0262044826719049"
      rpy="-2.65931138123085 0.212425490096565 -1.95364858543399" />
    <parent
      link="move_link" />
    <child
      link="31_link" />
    <axis
      xyz="0 0 -1" />
    <limit
      lower="-1.57"
      upper="1.57"
      effort="5000"
      velocity="2" />
    <mimic
      joint="move_joint"
      multiplier="1"
      offset="0" />
  </joint>
  <link
    name="32_link">
    <inertial>
      <origin
        xyz="0.0293216345242489 -0.0087610842961356 -0.0189999898761313"
        rpy="0 0 0" />
      <mass
        value="0.0122572498826078" />
      <inertia
        ixx="9.84650224489367E-07"
        ixy="-1.31798329819406E-06"
        ixz="1.04568287386481E-12"
        iyy="7.20145543798657E-06"
        iyz="-3.61695921990803E-13"
        izz="7.77268085824628E-06" />
    </inertial>
    <visual>
      <origin
        xyz="0 0 0"
        rpy="0 0 0" />
      <geometry>
        <mesh
          filename="package://threefingerv8/meshes/32_link.STL" />
      </geometry>
      <material
        name="">
        <color
          rgba="1 1 1 1" />
      </material>
    </visual>
    <collision>
      <origin
        xyz="0 0 0"
        rpy="0 0 0" />
      <geometry>
        <mesh
          filename="package://threefingerv8/meshes/32_link.STL" />
      </geometry>
    </collision>
  </link>
  <joint
    name="32_joint"
    type="revolute">
    <origin
      xyz="-0.013 0 0"
      rpy="3.14159265358979 0 3.14159265358979" />
    <parent
      link="31_link" />
    <child
      link="32_link" />
    <axis
      xyz="0 0 1" />
    <limit
      lower="-1.57"
      upper="1.57"
      effort="5000"
      velocity="2" />
    <mimic
      joint="31_joint"
      multiplier="1"
      offset="0" />
  </joint>
  <link
    name="12_link2">
    <inertial>
      <origin
        xyz="-0.0293208969248082 -0.00876107376234853 0.0190000001135646"
        rpy="0 0 0" />
      <mass
        value="0.0122579255984349" />
      <inertia
        ixx="9.8466089201607E-07"
        ixy="1.31799544484654E-06"
        ixz="-2.57676351638825E-14"
        iyy="7.20160465350243E-06"
        iyz="1.09652705676399E-14"
        izz="7.77283391142853E-06" />
    </inertial>
    <visual>
      <origin
        xyz="0 0 0"
        rpy="0 0 0" />
      <geometry>
        <mesh
          filename="package://threefingerv8/meshes/12_link2.STL" />
      </geometry>
      <material
        name="">
        <color
          rgba="1 1 1 1" />
      </material>
    </visual>
    <collision>
      <origin
        xyz="0 0 0"
        rpy="0 0 0" />
      <geometry>
        <mesh
          filename="package://threefingerv8/meshes/12_link2.STL" />
      </geometry>
    </collision>
  </link>
  <joint
    name="12_joint2"
    type="revolute">
    <origin
      xyz="0.019 0.024982 0.042875"
      rpy="1.5708 1.1355 -1.5708" />
    <parent
      link="base_link" />
    <child
      link="12_link2" />
    <axis
      xyz="0 0 1" />
    <limit
      lower="-1.57"
      upper="1.57"
      effort="5000"
      velocity="2" />
  </joint>
  <link
    name="22_link2">
    <inertial>
      <origin
        xyz="0.0293216343766779 -0.00876108435080183 -0.0190000103494336"
        rpy="0 0 0" />
      <mass
        value="0.0122572499897457" />
      <inertia
        ixx="9.84650226311452E-07"
        ixy="-1.31798330895562E-06"
        ixz="-1.09743409248296E-12"
        iyy="7.20145547037363E-06"
        iyz="3.40750820555156E-13"
        izz="7.77268089083732E-06" />
    </inertial>
    <visual>
      <origin
        xyz="0 0 0"
        rpy="0 0 0" />
      <geometry>
        <mesh
          filename="package://threefingerv8/meshes/22_link2.STL" />
      </geometry>
      <material
        name="">
        <color
          rgba="1 1 1 1" />
      </material>
    </visual>
    <collision>
      <origin
        xyz="0 0 0"
        rpy="0 0 0" />
      <geometry>
        <mesh
          filename="package://threefingerv8/meshes/22_link2.STL" />
      </geometry>
    </collision>
  </link>
  <joint
    name="22_joint2"
    type="revolute">
    <origin
      xyz="-0.031135 0.0039637 0.042875"
      rpy="1.5708 -1.1355 -2.618" />
    <parent
      link="base_link" />
    <child
      link="22_link2" />
    <axis
      xyz="0 0 -1" />
    <limit
      lower="-1.57"
      upper="1.57"
      effort="5000"
      velocity="2" />
  </joint>
  <link
    name="32_link2">
    <inertial>
      <origin
        xyz="0.0293216345242489 -0.00876108429613561 -0.0189999898761313"
        rpy="0 0 0" />
      <mass
        value="0.0122572498826078" />
      <inertia
        ixx="9.84650224489367E-07"
        ixy="-1.31798329819406E-06"
        ixz="1.04568287386481E-12"
        iyy="7.20145543798657E-06"
        iyz="-3.61695921990803E-13"
        izz="7.77268085824628E-06" />
    </inertial>
    <visual>
      <origin
        xyz="0 0 0"
        rpy="0 0 0" />
      <geometry>
        <mesh
          filename="package://threefingerv8/meshes/32_link2.STL" />
      </geometry>
      <material
        name="">
        <color
          rgba="1 1 1 1" />
      </material>
    </visual>
    <collision>
      <origin
        xyz="0 0 0"
        rpy="0 0 0" />
      <geometry>
        <mesh
          filename="package://threefingerv8/meshes/32_link2.STL" />
      </geometry>
    </collision>
  </link>
  <joint
    name="32_joint2"
    type="revolute">
    <origin
      xyz="0.012135 -0.028945 0.042875"
      rpy="1.5708 -1.1355 -0.5236" />
    <parent
      link="base_link" />
    <child
      link="32_link2" />
    <axis
      xyz="0 0 -1" />
    <limit
      lower="-1.57"
      upper="1.57"
      effort="5000"
      velocity="2" />
  </joint>
</robot>